<sdf version='1.6'>
  <world name='default'>
    <model name='ground_plane'>
      <static>1</static>
      <link name='link'>
        <collision name='collision'>
          <geometry>
            <plane>
              <normal>0 0 1</normal>
              <size>100 100</size>
            </plane>
          </geometry>
          <surface>
            <friction>
              <ode>
                <mu>100</mu>
                <mu2>50</mu2>
              </ode>
              <torsional>
                <ode/>
              </torsional>
            </friction>
            <contact>
              <ode/>
            </contact>
            <bounce/>
          </surface>
          <max_contacts>10</max_contacts>
        </collision>
        <visual name='visual'>
          <cast_shadows>0</cast_shadows>
          <geometry>
            <plane>
              <normal>0 0 1</normal>
              <size>100 100</size>
            </plane>
          </geometry>
          <material>
            <script>
              <uri>file://media/materials/scripts/gazebo.material</uri>
              <name>Gazebo/Grey</name>
            </script>
          </material>
        </visual>
        <self_collide>0</self_collide>
        <enable_wind>0</enable_wind>
        <kinematic>0</kinematic>
      </link>
    </model>
    <light name='sun' type='directional'>
      <cast_shadows>1</cast_shadows>
      <pose frame=''>0 0 10 0 -0 0</pose>
      <diffuse>0.8 0.8 0.8 1</diffuse>
      <specular>0.2 0.2 0.2 1</specular>
      <attenuation>
        <range>1000</range>
        <constant>0.9</constant>
        <linear>0.01</linear>
        <quadratic>0.001</quadratic>
      </attenuation>
      <direction>-0.5 0.1 -0.9</direction>
    </light>
    <gravity>0 0 -9.8</gravity>
    <magnetic_field>6e-06 2.3e-05 -4.2e-05</magnetic_field>
    <atmosphere type='adiabatic'/>
    <physics name='default_physics' default='0' type='ode'>
      <max_step_size>0.001</max_step_size>
      <real_time_factor>1</real_time_factor>
      <real_time_update_rate>1000</real_time_update_rate>
    </physics>
    <scene>
      <ambient>0.4 0.4 0.4 1</ambient>
      <background>0.7 0.7 0.7 1</background>
      <shadows>1</shadows>
    </scene>
    <wind/>
    <spherical_coordinates>
      <surface_model>EARTH_WGS84</surface_model>
      <latitude_deg>0</latitude_deg>
      <longitude_deg>0</longitude_deg>
      <elevation>0</elevation>
      <heading_deg>0</heading_deg>
    </spherical_coordinates>
    <model name='hero'>
      <link name='base_link'>
        <pose frame=''>0 0 0 0 -0 0</pose>
        <inertial>
          <pose frame=''>1e-05 0 0.003918 0 -0 0</pose>
          <mass>0.097</mass>
          <inertia>
            <ixx>4.61045e-05</ixx>
            <ixy>0</ixy>
            <ixz>-3.40825e-08</ixz>
            <iyy>5.03087e-05</iyy>
            <iyz>0</iyz>
            <izz>3.63564e-05</izz>
          </inertia>
        </inertial>
        <collision name='base_link_collision'>
          <pose frame=''>0 0 0 0 -0 -3.14159</pose>
          <geometry>
            <mesh>
              <scale>1 1 1</scale>
              <uri>/home/rezeck/mega/Projects/ROS/src/hero_common/hero_description/meshes/base_link.dae</uri>
            </mesh>
          </geometry>
          <max_contacts>10</max_contacts>
          <surface>
            <contact>
              <ode/>
            </contact>
            <bounce/>
            <friction>
              <torsional>
                <ode/>
              </torsional>
              <ode/>
            </friction>
          </surface>
        </collision>
        <collision name='base_link_fixed_joint_lump__hat_link_collision_1'>
          <pose frame=''>0.0001 0 0.038 0 -0 0</pose>
          <geometry>
            <mesh>
              <scale>1 1 1</scale>
              <uri>/home/rezeck/mega/Projects/ROS/src/hero_common/hero_description/meshes/hat.dae</uri>
            </mesh>
          </geometry>
          <surface>
            <contact>
              <ode/>
            </contact>
            <friction>
              <ode/>
              <torsional>
                <ode/>
              </torsional>
            </friction>
            <bounce/>
          </surface>
          <max_contacts>10</max_contacts>
        </collision>
        <visual name='base_link_visual'>
          <pose frame=''>0 0 0 0 -0 -3.14159</pose>
          <geometry>
            <mesh>
              <scale>1 1 1</scale>
              <uri>/home/rezeck/mega/Projects/ROS/src/hero_common/hero_description/meshes/base_link.dae</uri>
            </mesh>
          </geometry>
        </visual>
        <visual name='base_link_fixed_joint_lump__hat_link_visual_1'>
          <pose frame=''>0.0001 0 0.038 0 -0 0</pose>
          <geometry>
            <mesh>
              <scale>1 1 1</scale>
              <uri>/home/rezeck/mega/Projects/ROS/src/hero_common/hero_description/meshes/hat.dae</uri>
            </mesh>
          </geometry>
          <plugin name='gazebo_ros_model_color' filename='libgazebo_ros_model_color.so'>
            <robotNamespace>/</robotNamespace>
            <serviceName>/hat_color</serviceName>
            <color>0.4 0.0 0.0 1.0</color>
          </plugin>
          <material>
            <script>
              <uri>__default__</uri>
              <name>__default__</name>
            </script>
          </material>
        </visual>
        <gravity>1</gravity>
        <velocity_decay/>
        <self_collide>0</self_collide>
        <enable_wind>0</enable_wind>
        <kinematic>0</kinematic>
      </link>
      <link name='left_wheel_link'>
        <pose frame=''>0 -0.03115 0 0 -0 0</pose>
        <inertial>
          <pose frame=''>0 0 0 -1.5708 0 0</pose>
          <mass>0.01</mass>
          <inertia>
            <ixx>1.29652e-06</ixx>
            <ixy>0</ixy>
            <ixz>0</ixz>
            <iyy>1.29623e-06</iyy>
            <iyz>0</iyz>
            <izz>2.5547e-06</izz>
          </inertia>
        </inertial>
        <collision name='left_wheel_link_collision'>
          <pose frame=''>0 0 0 -1.5708 0 0</pose>
          <geometry>
            <mesh>
              <scale>1 1 1</scale>
              <uri>/home/rezeck/mega/Projects/ROS/src/hero_common/hero_description/meshes/wheel.dae</uri>
            </mesh>
          </geometry>
          <max_contacts>10</max_contacts>
          <surface>
            <contact>
              <ode/>
            </contact>
            <bounce/>
            <friction>
              <torsional>
                <ode/>
              </torsional>
              <ode/>
            </friction>
          </surface>
        </collision>
        <visual name='left_wheel_link_visual'>
          <pose frame=''>0 0 0 -1.5708 0 0</pose>
          <geometry>
            <mesh>
              <scale>1 1 1</scale>
              <uri>/home/rezeck/mega/Projects/ROS/src/hero_common/hero_description/meshes/wheel.dae</uri>
            </mesh>
          </geometry>
        </visual>
        <self_collide>0</self_collide>
        <enable_wind>0</enable_wind>
        <kinematic>0</kinematic>
      </link>
      <joint name='left_wheel_joint' type='revolute'>
        <child>left_wheel_link</child>
        <parent>base_link</parent>
        <axis>
          <xyz>0 1 0</xyz>
          <limit>
            <lower>-1e+16</lower>
            <upper>1e+16</upper>
          </limit>
          <dynamics>
            <damping>0</damping>
            <friction>0</friction>
            <spring_reference>0</spring_reference>
            <spring_stiffness>0</spring_stiffness>
          </dynamics>
          <use_parent_model_frame>1</use_parent_model_frame>
        </axis>
      </joint>
      <link name='right_wheel_link'>
        <pose frame=''>0 0.03115 0 0 -0 0</pose>
        <inertial>
          <pose frame=''>0 0 0 1.5708 -0 0</pose>
          <mass>0.01</mass>
          <inertia>
            <ixx>1.29652e-06</ixx>
            <ixy>0</ixy>
            <ixz>0</ixz>
            <iyy>1.29623e-06</iyy>
            <iyz>0</iyz>
            <izz>2.5547e-06</izz>
          </inertia>
        </inertial>
        <collision name='right_wheel_link_collision'>
          <pose frame=''>0 0 0 1.5708 -0 0</pose>
          <geometry>
            <mesh>
              <scale>1 1 1</scale>
              <uri>/home/rezeck/mega/Projects/ROS/src/hero_common/hero_description/meshes/wheel.dae</uri>
            </mesh>
          </geometry>
          <max_contacts>10</max_contacts>
          <surface>
            <contact>
              <ode/>
            </contact>
            <bounce/>
            <friction>
              <torsional>
                <ode/>
              </torsional>
              <ode/>
            </friction>
          </surface>
        </collision>
        <visual name='right_wheel_link_visual'>
          <pose frame=''>0 0 0 1.5708 -0 0</pose>
          <geometry>
            <mesh>
              <scale>1 1 1</scale>
              <uri>/home/rezeck/mega/Projects/ROS/src/hero_common/hero_description/meshes/wheel.dae</uri>
            </mesh>
          </geometry>
        </visual>
        <self_collide>0</self_collide>
        <enable_wind>0</enable_wind>
        <kinematic>0</kinematic>
      </link>
      <joint name='right_wheel_joint' type='revolute'>
        <child>right_wheel_link</child>
        <parent>base_link</parent>
        <axis>
          <xyz>0 1 0</xyz>
          <limit>
            <lower>-1e+16</lower>
            <upper>1e+16</upper>
          </limit>
          <dynamics>
            <damping>0</damping>
            <friction>0</friction>
            <spring_reference>0</spring_reference>
            <spring_stiffness>0</spring_stiffness>
          </dynamics>
          <use_parent_model_frame>1</use_parent_model_frame>
        </axis>
      </joint>
      <plugin name='gazebo_ros_control' filename='libgazebo_ros_control.so'>
        <robotNamespace>/</robotNamespace>
      </plugin>
      <static>0</static>
      <plugin name='differential_drive_controller' filename='libgazebo_ros_diff_drive.so'>
        <alwaysOn>1</alwaysOn>
        <legacyMode>0</legacyMode>
        <updateRate>100</updateRate>
        <robotNamespace>/</robotNamespace>
        <leftJoint>left_wheel_joint</leftJoint>
        <rightJoint>right_wheel_joint</rightJoint>
        <wheelSeparation>0.0623</wheelSeparation>
        <wheelDiameter>0.0496</wheelDiameter>
        <torque>0.3</torque>
        <commandTopic>cmd_vel</commandTopic>
        <odometryTopic>odom</odometryTopic>
        <odometryFrame>odom</odometryFrame>
        <odometrySource>world</odometrySource>
        <publishTf>1</publishTf>
        <rosDebugLevel>na</rosDebugLevel>
        <wheelAcceleration>0</wheelAcceleration>
        <wheelTorque>0.3</wheelTorque>
        <robotBaseFrame>base_link</robotBaseFrame>
        <publishWheelTF>0</publishWheelTF>
        <publishWheelJointState>0</publishWheelJointState>
        <covariance_x>0.00001</covariance_x>
        <covariance_y>0.00001</covariance_y>
        <covariance_yaw>0.01</covariance_yaw>
      </plugin>
      <pose frame=''>0 0 0.1 0 -0 0</pose>
    </model>
    <state world_name='default'>
      <sim_time>32 690000000</sim_time>
      <real_time>44 66124564</real_time>
      <wall_time>1537305787 539844473</wall_time>
      <iterations>32690</iterations>
      <model name='ground_plane'>
        <pose frame=''>0 0 0 0 -0 0</pose>
        <scale>1 1 1</scale>
        <link name='link'>
          <pose frame=''>0 0 0 0 -0 0</pose>
          <velocity>0 0 0 0 -0 0</velocity>
          <acceleration>0 0 0 0 -0 0</acceleration>
          <wrench>0 0 0 0 -0 0</wrench>
        </link>
      </model>
      <model name='hero'>
        <pose frame=''>-0.000535 -0.000357 0.025185 -0.000838 0.032123 -0.013423</pose>
        <scale>1 1 1</scale>
        <link name='base_link'>
          <pose frame=''>-0.000535 -0.000357 0.025185 -0.000838 0.032123 -0.013423</pose>
          <velocity>6.3e-05 -2.4e-05 1e-06 8.1e-05 0.003953 6.2e-05</velocity>
          <acceleration>0.201639 -0.049149 -0.00045 -2.96082 1.54156 -2.39936</acceleration>
          <wrench>0.019559 -0.004767 -4.4e-05 0 -0 0</wrench>
        </link>
        <link name='left_wheel_link'>
          <pose frame=''>-0.000952 -0.031503 0.025211 -0.000671 -0.02197 -0.013385</pose>
          <velocity>6.6e-05 -2.2e-05 -4e-06 0.000291 0.002645 3.6e-05</velocity>
          <acceleration>0.196141 -0.040911 -0.008943 1.51758 1.4953 0.664605</acceleration>
          <wrench>0.001961 -0.000409 -8.9e-05 0 -0 0</wrench>
        </link>
        <link name='right_wheel_link'>
          <pose frame=''>-0.000118 0.03079 0.025159 -0.001013 -0.007017 -0.013382</pose>
          <velocity>7e-05 -1.7e-05 -9e-06 0.001251 0.002803 -6e-05</velocity>
          <acceleration>0.16512 -0.039355 -0.017744 1.4752 0.27694 0.540769</acceleration>
          <wrench>0.001651 -0.000394 -0.000177 0 -0 0</wrench>
        </link>
      </model>
      <light name='sun'>
        <pose frame=''>0 0 10 0 -0 0</pose>
      </light>
    </state>
    <gui fullscreen='0'>
      <camera name='user_camera'>
        <pose frame=''>0.449329 -0.399788 0.246821 0 0.275643 2.35619</pose>
        <view_controller>orbit</view_controller>
        <projection_type>perspective</projection_type>
      </camera>
    </gui>
  </world>
</sdf>
