<?xml version="1.0" encoding="utf-8"?>
<!-- =================================================================================== -->
<!-- |    This document was autogenerated by xacro from hero.urdf.xacro                | -->
<!-- |    EDITING THIS FILE BY HAND IS NOT RECOMMENDED                                 | -->
<!-- =================================================================================== -->
<robot name="hero_0">
  <!-- Here was the base link definitions -->
  <link name="base_link">
    <visual>
      <origin rpy="0 0 1.57079632679" xyz="0 0 0"/>
      <geometry>
        <mesh filename="package://hero_description/meshes/base_link.obj" scale="1 1 1"/>
      </geometry>
    </visual>
    <collision>
      <origin rpy="0 0 1.57079632679" xyz="0 0 0.0121"/>
      <geometry>
        <!-- <cylinde size="0.068 0.068 0.048"/> -->
        <cylinder length="0.042" radius="0.037"/>
        <!-- <mesh filename="package://hero_description/meshes/base_link.dae" scale="1 1 1"/> -->
      </geometry>
    </collision>
    <inertial>
      <mass value="0.090"/>
      <origin rpy="1.57079632679 0 0" xyz="0 0.0002 0"/>
      <inertia ixx="5.925e-05" ixy="0" ixz="0" iyy="5.925e-05" iyz="0" izz="5.5125e-05"/>
    </inertial>
  </link>
  <gazebo reference="base_link">
    <gravity>1</gravity>
    <mu1 value="0.01"/>
    <mu2 value="0.01"/>
    <!-- <maxVel value="0.10"/>  -->
    <maxContacts>4</maxContacts>
    <selfCollide>1</selfCollide>
  </gazebo>
  <!--  Here was the hat joint and link -->
  <joint name="hat_joint" type="fixed">
    <origin rpy="0 0 0" xyz="-0.00245 -0.00216 0.06027"/>
    <parent link="base_link"/>
    <child link="hat_link"/>
  </joint>
  <link name="hat_link">
    <visual>
      <origin rpy="0 0 0" xyz="0 0 0"/>
      <geometry>
        <mesh filename="package://hero_description/meshes/hat.obj" scale="1 1 1"/>
      </geometry>
    </visual>
    <collision>
      <origin rpy="0 0 0" xyz="0 0 0"/>
      <geometry>
        <!-- <box size="0.068 0.068 0.02"/> -->
        <!-- <cylinder length="0.02" radius="0.040"/> -->
        <mesh filename="package://hero_description/meshes/hat.obj" scale="1 1 1"/>
      </geometry>
    </collision>
    <inertial>
      <mass value="0.010"/>
      <origin rpy="0 0 0" xyz="0 0 0"/>
      <inertia ixx="3.39583333333e-06" ixy="0" ixz="0" iyy="3.39583333333e-06" iyz="0" izz="6.125e-06"/>
    </inertial>
  </link>
  <gazebo reference="hat_link">
    <gravity>1</gravity>
    <!-- <mu1 value="0.005"/>
    <mu2 value="0.005"/> -->
    <maxVel value="0.10"/>
    <maxContacts>0</maxContacts>
    <selfCollide>0</selfCollide>
  </gazebo>
  <!--  Here was the left wheel joint and link -->
  <joint name="left_wheel_joint" type="continuous">
    <parent link="base_link"/>
    <child link="left_wheel_link"/>
    <origin rpy="0 0 0" xyz="0.0 0.0323 0.01548"/>
    <axis xyz="0 1 0"/>
    <limit effort="0.1" velocity="0.3"/>
    <dynamics damping="0.0001" friction="0.0"/>
  </joint>
  <link name="left_wheel_link">
    <visual>
      <origin rpy="0 0 0" xyz="0 0 0.0"/>
      <geometry>
        <mesh filename="package://hero_description/meshes/wheel.obj" scale="1 1 1"/>
      </geometry>
    </visual>
    <collision>
      <origin rpy="1.57079632679 0 0" xyz="0 0 0.0"/>
      <geometry>
        <cylinder length="0.008" radius="0.025"/>
      </geometry>
    </collision>
    <inertial>
      <mass value="0.020"/>
      <origin rpy="1.57079632679 0 0" xyz="0 0 0"/>
      <inertia ixx="1.61583333333e-06" ixy="0" ixz="0" iyy="1.61583333333e-06" iyz="0" izz="3.125e-06"/>
    </inertial>
  </link>
  <gazebo reference="left_wheel_link">
    <mu1 value="1.0"/>
    <mu2 value="1.0"/>
    <!-- <maxVel value="0.10"/>  -->
    <!-- <kp value="10000000.0"/>
    <kd value="1.0"/>
    <fdir1 value="1 0 0"/> -->
    <gravity>1</gravity>
    <maxContacts>4</maxContacts>
    <selfCollide>0</selfCollide>
  </gazebo>
  <!--  Here was the right wheel joint and link -->
  <joint name="right_wheel_joint" type="continuous">
    <axis xyz="0 1 0"/>
    <limit effort="0.1" velocity="0.3"/>
    <dynamics damping="0.0001" friction="0"/>
    <origin rpy="0 0 0" xyz="0.0 -0.0323 0.01548"/>
    <parent link="base_link"/>
    <child link="right_wheel_link"/>
  </joint>
  <link name="right_wheel_link">
    <visual>
      <origin rpy="-3.14159265359 0 0" xyz="0 0 0.0"/>
      <geometry>
        <mesh filename="package://hero_description/meshes/wheel.obj" scale="1 1 1"/>
      </geometry>
    </visual>
    <collision>
      <origin rpy="-1.57079632679 0 0" xyz="0 0 0.0"/>
      <geometry>
        <cylinder length="0.008" radius="0.025"/>
      </geometry>
    </collision>
    <inertial>
      <mass value="0.020"/>
      <origin rpy="-1.57079632679 0 0" xyz="0 0 0"/>
      <inertia ixx="1.61583333333e-06" ixy="0" ixz="0" iyy="1.61583333333e-06" iyz="0" izz="3.125e-06"/>
    </inertial>
  </link>
  <gazebo reference="right_wheel_link">
    <mu1 value="1.0"/>
    <mu2 value="1.0"/>
    <!-- <maxVel value="0.10"/>  -->
    <!-- <kp value="10000000.0"/>
    <kd value="1.0"/>
    <fdir1 value="1 0 0"/> -->
    <gravity>1</gravity>
    <maxContacts>4</maxContacts>
    <selfCollide>0</selfCollide>
  </gazebo>
  <!-- ros_control plugin -->
  <gazebo>
    <plugin filename="libgazebo_ros_control.so" name="gazebo_ros_control">
      <!--robotNamespace>/</robotNamespace-->
      <legacyModeNS>true</legacyModeNS>
      <controlPeriod>0.60</controlPeriod>
    </plugin>
  </gazebo>
  <!-- Differential drive controller plugin -->
  <gazebo>
    <plugin filename="libgazebo_ros_diff_drive.so" name="differential_drive_controller">
      <!--robotNamespace>/</robotNamespace-->
      <alwaysOn>true</alwaysOn>
      <updateRate>15</updateRate>
      <leftJoint>left_wheel_joint</leftJoint>
      <rightJoint>right_wheel_joint</rightJoint>
      <wheelSeparation>0.0646</wheelSeparation>
      <wheelDiameter>0.05</wheelDiameter>
      <torque>0.03</torque>
      <commandTopic>cmd_vel</commandTopic>
      <odometryTopic>odom</odometryTopic>
      <odometryFrame>odom</odometryFrame>
      <odometrySource>world</odometrySource>
      <robotBaseFrame>base_link</robotBaseFrame>
      <rosDebugLevel>na</rosDebugLevel>
      <legacyMode>true</legacyMode>
      <publishOdomTF>true</publishOdomTF>
      <publishWheelTF>true</publishWheelTF>
      <publishWheelJointState>false</publishWheelJointState>
      <wheelAcceleration>0.0</wheelAcceleration>
      <publishTf>true</publishTf>
      <wheelTorque>0.5</wheelTorque>
    </plugin>
  </gazebo>
  <!-- Color plugin -->
  <gazebo reference="hat_link">
    <visual>
      <plugin filename="libgazebo_ros_hero_color.so" name="libgazebo_ros_hero_color">
        <!--robotNamespace>/</robotNamespace-->
        <serviceName>led</serviceName>
        <topicName>led</topicName>
        <color>0.0 0.5 0.9 1.0</color>
      </plugin>
    </visual>
  </gazebo>
  <!-- Here is the left joint transmission to gazebo -->
  <transmission name="left_wheel_tran">
    <type>transmission_interface/SimpleTransmission</type>
    <joint name="left_wheel_joint">
      <hardwareInterface>hardware_interface/EffortJointInterface</hardwareInterface>
    </joint>
    <actuator name="left_wheel_motor">
      <mechanicalReduction>1</mechanicalReduction>
      <hardwareInterface>hardware_interface/EffortJointInterface</hardwareInterface>
    </actuator>
  </transmission>
  <!-- Here is the right joint transmission to gazebo -->
  <transmission name="right_wheel_tran">
    <type>transmission_interface/SimpleTransmission</type>
    <joint name="right_wheel_joint">
      <hardwareInterface>hardware_interface/EffortJointInterface</hardwareInterface>
    </joint>
    <actuator name="right_wheel_motor">
      <mechanicalReduction>1</mechanicalReduction>
      <hardwareInterface>hardware_interface/EffortJointInterface</hardwareInterface>
    </actuator>
  </transmission>
  <!-- Here is the laser link -->
  <joint name="laser_joint" type="fixed">
    <axis xyz="0 1 0"/>
    <origin rpy="0 0 0" xyz="0 0 0.051"/>
    <parent link="base_link"/>
    <child link="laser_link"/>
  </joint>
  <link name="laser_link">
    <collision>
      <origin rpy="0 0 0" xyz="0 0 0"/>
      <geometry>
        <box size="0.001 0.001 0.001"/>
      </geometry>
    </collision>
    <visual>
      <origin rpy="0 0 0" xyz="0 0 0"/>
      <geometry>
        <box size="0.001 0.001 0.001"/>
      </geometry>
    </visual>
    <inertial>
      <mass value="1e-5"/>
      <origin rpy="0 0 0" xyz="0 0 0"/>
      <inertia ixx="1e-6" ixy="0" ixz="0" iyy="1e-6" iyz="0" izz="1e-6"/>
    </inertial>
  </link>
  <gazebo reference="laser_link">
    <gravity>1</gravity>
    <!-- <mu1 value="0.005"/>
    <mu2 value="0.005"/> -->
    <maxVel value="0.10"/>
    <maxContacts>0</maxContacts>
    <selfCollide>0</selfCollide>
  </gazebo>
  <!-- Laser plugin -->
  <gazebo reference="laser_link">
    <sensor name="hero_laser_sensor" type="ray">
      <pose>0 0 0.051 0 0 0</pose>
      <visualize>false</visualize>
      <update_rate>10</update_rate>
      <ray>
        <scan>
          <horizontal>
            <samples>16</samples>
            <resolution>1</resolution>
            <min_angle>-3.14159265359</min_angle>
            <max_angle>3.14159265359</max_angle>
          </horizontal>
        </scan>
        <range>
          <min>0.037</min>
          <max>0.50</max>
          <resolution>0.01</resolution>
        </range>
      </ray>
      <plugin filename="libgazebo_ros_laser.so" name="gazebo_ros_hero_laser">
        <topicName>laser</topicName>
        <frameName>laser_link</frameName>
        <gaussianNoise>0.001</gaussianNoise>
        <updateRate>10</updateRate>
      </plugin>
    </sensor>
  </gazebo>
  <!-- IMU plugin -->
<!--   <gazebo>
    <plugin filename="libgazebo_ros_imu.so" name="imu_plugin">
      <alwaysOn>true</alwaysOn>
      <bodyName>hat_link</bodyName>
      <topicName>imu</topicName>
      <serviceName>imu_service</serviceName>
      <gaussianNoise>0.0</gaussianNoise>
      <updateRate>20.0</updateRate>
      <xyzOffset>0 0 0</xyzOffset>
      <rpyOffset>0 0 0</rpyOffset>
    </plugin>
  </gazebo> -->
</robot>
